scriptPath,detail,startTime,endTime,duration,result
/Users/tylan/Desktop/myAuty/Auty/scripts/scripts/quanzi/get_messages_test.py,No exception in execute_script method.,2016-10-11 21:11:11.272307,2016-10-11 21:11:12.170694,0.8983869999999999,"{""result"":100,""messages"":[],""resultDesc"":""成功""}
10919
passed
passed
select * from ts_messages where userid = '10919'
Traceback (most recent call last):
  File ""/Users/tylan/Desktop/myAuty/Auty/scripts/scripts/quanzi/get_messages_test.py"", line 38, in <module>
    basic_assert(r,userId)
  File ""/Users/tylan/Desktop/myAuty/Auty/scripts/scripts/quanzi/get_messages_test.py"", line 33, in basic_assert
    print get_messages(str(userId))
  File ""/Users/tylan/Desktop/myAuty/Auty/utils/get_messages.py"", line 9, in get_messages
    r = exec_sql(sql,qz_host,qz_user,qz_pwd,qz_db_name)
  File ""/Users/tylan/Desktop/myAuty/Auty/utils/execute_sql_mysql.py"", line 15, in exec_sql
    results = interact_mysql(sql,dbHost,userName,pwd,dbName)
  File ""/Users/tylan/Desktop/myAuty/Auty/utils/execute_sql_mysql.py"", line 7, in interact_mysql
    cur.execute(sql)
  File ""/Library/Python/2.7/site-packages/pymysql/cursors.py"", line 166, in execute
    result = self._query(query)
  File ""/Library/Python/2.7/site-packages/pymysql/cursors.py"", line 322, in _query
    conn.query(q)
  File ""/Library/Python/2.7/site-packages/pymysql/connections.py"", line 835, in query
    self._affected_rows = self._read_query_result(unbuffered=unbuffered)
  File ""/Library/Python/2.7/site-packages/pymysql/connections.py"", line 1019, in _read_query_result
    result.read()
  File ""/Library/Python/2.7/site-packages/pymysql/connections.py"", line 1302, in read
    first_packet = self.connection._read_packet()
  File ""/Library/Python/2.7/site-packages/pymysql/connections.py"", line 981, in _read_packet
    packet.check_error()
  File ""/Library/Python/2.7/site-packages/pymysql/connections.py"", line 393, in check_error
    err.raise_mysql_exception(self._data)
  File ""/Library/Python/2.7/site-packages/pymysql/err.py"", line 107, in raise_mysql_exception
    raise errorclass(errno, errval)
pymysql.err.ProgrammingError: (1146, u""Table 'lottqz.ts_messages' doesn't exist"")
"
,Exception in execute_script method: [Errno 2] No such file or directory: '',2016-10-11 21:11:12.170904,2016-10-11 21:11:12.171047,0.000143,
