scriptPath,detail,startTime,endTime,duration,result
/Users/tylan/Desktop/myAuty/Auty/scripts/scripts/quanzi/batch_follow_test.py,No exception in execute_script method.,2016-10-10 22:28:03.597059,2016-10-10 22:28:04.241160,0.6441009999999999,"passed
passed
"
/Users/tylan/Desktop/myAuty/Auty/scripts/scripts/quanzi/collect_post_test.py,No exception in execute_script method.,2016-10-10 22:28:04.241287,2016-10-10 22:28:04.877074,0.635787,"{""result"":100,""resultDesc"":""收藏成功!"",""collectStatus"":""1""}
Traceback (most recent call last):
  File ""/Users/tylan/Desktop/myAuty/Auty/scripts/scripts/quanzi/collect_post_test.py"", line 41, in <module>
    collect_assert(collect_post_test('runcheck5@163.com','1132664','1'))
  File ""/Users/tylan/Desktop/myAuty/Auty/scripts/scripts/quanzi/collect_post_test.py"", line 30, in collect_assert
    tylan_assert(jsonResult['resultDesc'],u""成功"")
  File ""/Users/tylan/Desktop/myAuty/Auty/utils/utils.py"", line 17, in tylan_assert
    print 'failed,actual result:'+str(actual).encode('utf8')
UnicodeEncodeError: 'ascii' codec can't encode characters in position 0-3: ordinal not in range(128)
"
/Users/tylan/Desktop/myAuty/Auty/scripts/scripts/quanzi/follow_test.py,No exception in execute_script method.,2016-10-10 22:28:04.877186,2016-10-10 22:28:05.970233,0.09304699999999999,"passed
passed
passed
"
/Users/tylan/Desktop/myAuty/Auty/scripts/scripts/quanzi/login_test.py,No exception in execute_script method.,2016-10-10 22:28:05.970327,2016-10-10 22:28:06.110028,0.139701,"No login interface.
"
/Users/tylan/Desktop/myAuty/Auty/scripts/scripts/quanzi/post_info_test.py,No exception in execute_script method.,2016-10-10 22:28:06.110130,2016-10-10 22:28:06.768720,0.65859,"passed
passed
"
/Users/tylan/Desktop/myAuty/Auty/scripts/scripts/quanzi/report_test.py,No exception in execute_script method.,2016-10-10 22:28:06.768813,2016-10-10 22:28:06.987699,0.218886,"passed
passed
"
/Users/tylan/Desktop/myAuty/Auty/scripts/scripts/quanzi/search_users_test.py,No exception in execute_script method.,2016-10-10 22:28:06.987803,2016-10-10 22:28:07.571091,0.583288,"passed
passed
passed
"
/Users/tylan/Desktop/myAuty/Auty/scripts/scripts/quanzi/send_post_test.py,No exception in execute_script method.,2016-10-10 22:28:07.571189,2016-10-10 22:28:08.184356,0.613167,"Traceback (most recent call last):
  File ""/Users/tylan/Desktop/myAuty/Auty/scripts/scripts/quanzi/send_post_test.py"", line 36, in <module>
    basic_assert(send_post_test('runcheck5@163.com'))
  File ""/Users/tylan/Desktop/myAuty/Auty/scripts/scripts/quanzi/send_post_test.py"", line 32, in basic_assert
    tylan_assert(jsonResult['resultDesc'],u""发帖成功!"")
  File ""/Users/tylan/Desktop/myAuty/Auty/utils/utils.py"", line 17, in tylan_assert
    print 'failed,actual result:'+str(actual).encode('utf8')
UnicodeEncodeError: 'ascii' codec can't encode characters in position 0-1: ordinal not in range(128)
"
/Users/tylan/Desktop/myAuty/Auty/scripts/scripts/quanzi/upload_images_test.py,No exception in execute_script method.,2016-10-10 22:28:08.184465,2016-10-10 22:28:08.797765,0.6133,"passed
passed
"
