scriptPath,detail,startTime,endTime,duration,result
/Users/tylan/Desktop/myAuty/Auty/scripts/scripts/quanzi/get_messages_test.py,No exception in execute_script method.,2016-10-11 21:05:58.066624,2016-10-11 21:05:58.746472,0.679848,"Traceback (most recent call last):
  File ""/Users/tylan/Desktop/myAuty/Auty/scripts/scripts/quanzi/get_messages_test.py"", line 34, in <module>
    r,userId = get_messages_test('runcheck5@163.com')
  File ""/Users/tylan/Desktop/myAuty/Auty/scripts/scripts/quanzi/get_messages_test.py"", line 23, in get_messages_test
    r = s.post(url, data = data)
  File ""/Library/Python/2.7/site-packages/requests/sessions.py"", line 508, in post
    return self.request('POST', url, data=data, json=json, **kwargs)
  File ""/Library/Python/2.7/site-packages/requests/sessions.py"", line 465, in request
    resp = self.send(prep, **send_kwargs)
  File ""/Library/Python/2.7/site-packages/requests/sessions.py"", line 573, in send
    r = adapter.send(request, **kwargs)
  File ""/Library/Python/2.7/site-packages/requests/adapters.py"", line 415, in send
    raise ConnectionError(err, request=request)
requests.exceptions.ConnectionError: ('Connection aborted.', error(61, 'Connection refused'))
"
,Exception in execute_script method: [Errno 2] No such file or directory: '',2016-10-11 21:05:58.746656,2016-10-11 21:05:58.746797,0.00014099999999999998,
