scriptPath,detail,startTime,endTime,duration,result
/Users/tylan/Desktop/myAuty/Auty/scripts/scripts/quanzi/get_messages_test.py,No exception in execute_script method.,2016-10-11 19:58:52.083449,2016-10-11 20:00:09.294202,0.210753,"Traceback (most recent call last):
  File ""/Users/tylan/Desktop/myAuty/Auty/scripts/scripts/quanzi/get_messages_test.py"", line 32, in <module>
    r = get_messages_test('runcheck5@163.com')
  File ""/Users/tylan/Desktop/myAuty/Auty/scripts/scripts/quanzi/get_messages_test.py"", line 19, in get_messages_test
    'userId':get_lottery_user_id(accountId),
  File ""/Users/tylan/Desktop/myAuty/Auty/utils/get_lottery_user_id.py"", line 8, in get_lottery_user_id
    r = exec_sql(sql,qz_host,qz_user,qz_pwd,qz_db_name)
  File ""/Users/tylan/Desktop/myAuty/Auty/utils/execute_sql_mysql.py"", line 15, in exec_sql
    results = interact_mysql(sql,dbHost,userName,pwd,dbName)
  File ""/Users/tylan/Desktop/myAuty/Auty/utils/execute_sql_mysql.py"", line 5, in interact_mysql
    conn = pymysql.connect(host=dbHost, user=userName, passwd=pwd, port=3309, db=dbName, charset='utf8')
  File ""/Library/Python/2.7/site-packages/pymysql/__init__.py"", line 90, in Connect
    return Connection(*args, **kwargs)
  File ""/Library/Python/2.7/site-packages/pymysql/connections.py"", line 688, in __init__
    self.connect()
  File ""/Library/Python/2.7/site-packages/pymysql/connections.py"", line 937, in connect
    raise exc
pymysql.err.OperationalError: (2003, ""Can't connect to MySQL server on '10.120.240.252' ([Errno 60] Operation timed out)"")
"
,Exception in execute_script method: [Errno 2] No such file or directory: '',2016-10-11 20:00:09.294415,2016-10-11 20:00:09.294578,0.000163,
